Workbook

Sheet 說明
A1: 負面新聞離線覆核：第二批（待人工覆核剩餘＋已分類 L3）
A2: 產生日期：2026-10-26 筆數：645（待人工覆核 315、已分類 L3 330）
A4: 怎麼填（只動黃色欄位）
A5: 1. 最終決定（R 欄）：已預填我的建議。維持＝沿用目前分類；修改＝改成「新事件代碼」；排除＝記為 NOT_RELEVANT、Level 0、Action「排除、不納入風險事件」。
A6: 2. 新事件代碼（S 欄）：只有「修改」才需要，從下拉選單選；新事件中文與新 Level 會自動帶出。
A7: 3. 更正公司（V 欄）、更正Ticker（W 欄）：只在公司歸屬錯誤或 Ticker 空白時填寫，空白代表不更正。已依 S&P 500 清單預填 Ticker 空白的列。
A8: 4. 覆核註記（Y 欄）、覆核人（Z 欄）：請填你的姓名；註記可空白。
A9: 5. 把握程度為「低」或「建議看原文」為「是」的列（紅字），建議點標題開原文確認。
A10: 6. 檢查欄（X）若出現紅字，表示該列填寫不完整。
A11: 7. 不要修改 news_id、人工版本欄；上傳時靠這兩欄對應與防衝突。
A12: 8. 確認後請另存為「檔名_已確認.xlsx」。
A14: 我的建議統計（即時計算）
A15: 建議維持： | B15: =COUNTIF(覆核!$M$2:$M$646,"維持") -> 173
A16: 建議修改： | B16: =COUNTIF(覆核!$M$2:$M$646,"修改") -> 22
A17: 建議排除： | B17: =COUNTIF(覆核!$M$2:$M$646,"排除") -> 450
A18: 最終決定尚未填寫的列數： | B18: =COUNTBLANK(覆核!$R$2:$R$646) -> 0
A20: 限制：我只看資料中的標題與摘要，沒有逐篇開原文；建議不保證全對，最終由你確認。Level 顏色：5 紅、4 橘、3 黃、2 淡藍、1 淺灰、0 深灰。

Sheet 覆核
A1: 序號 | B1: 日期 | C1: Ticker | D1: 公司 | E1: 標題（點擊開原文） | F1: 中文標題／摘要 | G1: 來源 | H1: FinBERT | I1: 目前事件代碼 | J1: 目前事件中文 | K1: 目前Level | L1: 目前分類狀態 | M1: 建議 | N1: 建議事件代碼 | O1: 把握程度 | P1: 理由 | Q1: 建議看原文 | R1: 最終決定 | S1: 新事件代碼 | T1: 新事件中文 | U1: 新Level | V1: 更正公司 | W1: 更正Ticker | X1: 檢查 | Y1: 覆核註記 | Z1: 覆核人 | AA1: news_id | AB1: 人工版本
A2: 1 | B2: 2026-10-23 | C2: CRWV | D2: CoreWeave, Inc. | E2: 股價月內跌36%、CDS利差飆升AI雲服務商CoreWeave(CRWV.US)深陷信心危機作者智通財經 | F2: CoreWeave 股價在一個月內下跌36%，同時其 CDS 利差急劇擴大，顯示市場對其信用風險的擔憂升高，但並未有任何明確的違約或破產訊息。 | G2: Investing.com 香港 - 股市報價& 財經新聞 | I2: CDS_SPREAD_WIDENING | J2: CDS利差擴大／信用風險升高 | K2: 3 | L2: 已分類 | M2: 維持 | O2: 高 | P2: CoreWeave 股價月內跌 36% 且 CDS 利差急升，市場對信用的信心下降。 | R2: 維持 | T2: =IF(R2="維持",J2,IF(R2="排除","無關新聞事件",IFERROR(INDEX(事件規則!$B$2:$B$53,MATCH(S2,事件規則!$A$2:$A$53,0)),""))) -> CDS利差擴大／信用風險升高 | U2: =IF(R2="維持",K2,IF(R2="排除",0,IFERROR(INDEX(事件規則!$C$2:$C$53,MATCH(S2,事件規則!$A$2:$A$53,0)),""))) -> 3 | X2: =IF(AND(R2="修改",S2=""),"請選新事件代碼",IF(AND(R2<>"修改",S2<>""),"只有「修改」才需填代碼","")) | AA2: a409987af5a8c21a78698323
A3: 2 | B3: 2026-10-23 | C3: CRWV | D3: CoreWeave, Inc. | E3: 股價月內跌36%、CDS利差飆升 AI雲服務商CoreWeave深陷信心危機 | F3: CoreWeave 股價在一個月內下跌36%，同時 CDS 利差急劇擴大，顯示市場對其信用風險的擔憂升高，但並未確認任何違約或其他重大事件。 | G3: Moomoo | I3: CDS_SPREAD_WIDENING | J3: CDS利差擴大／信用風險升高 | K3: 3 | L3: 已分類 | M3: 維持 | O3: 高 | P3: CoreWeave 股價月內跌 36% 且 CDS 利差急升，市場對信用的信心下降。 | R3: 維持 | T3: =IF(R3="維持",J3,IF(R3="排除","無關新聞事件",IFERROR(INDEX(事件規則!$B$2:$B$53,MATCH(S3,事件規則!$A$2:$A$53,0)),""))) -> CDS利差擴大／信用風險升高 | U3: =IF(R3="維持",K3,IF(R3="排除",0,IFERROR(INDEX(事件規則!$C$2:$C$53,MATCH(S3,事件規則!$A$2:$A$53,0)),""))) -> 3 | X3: =IF(AND(R3="修改",S3=""),"請選新事件代碼",IF(AND(R3<>"修改",S3<>""),"只有「修改」才需填代碼","")) | AA3: 2d665ff894609ba4dcbe3fbf
A4: 3 | B4: 2026-10-23 | C4: CRWV | D4: CoreWeave, Inc. | E4: CoreWeave Stock Tumbles as Bernstein Cuts Target on AI Debt Fears | F4: 核心算力公司CoreWeave因市場對其AI債務的擔憂，股價大幅下跌，顯示投資者對其信用風險的擔憂升高。 | G4: TradingView | I4: CDS_SPREAD_WIDENING | J4: CDS利差擴大／信用風險升高 | K4: 3 | L4: 已分類 | M4: 維持 | O4: 中 | P4: Bernstein 因 AI 債務疑慮調降 CoreWeave 目標價，股價下跌。 | R4: 維持 | T4: =IF(R4="維持",J4,IF(R4="排除","無關新聞事件",IFERROR(INDEX(事件規則!$B$2:$B$53,MATCH(S4,事件規則!$A$2:$A$53,0)),""))) -> CDS利差擴大／信用風險升高 | U4: =IF(R4="維持",K4,IF(R4="排除",0,IFERROR(INDEX(事件規則!$C$2:$C$53,MATCH(S4,事件規則!$A$2:$A$53,0)),""))) -> 3 | X4: =IF(AND(R4="修改",S4=""),"請選新事件代碼",IF(AND(R4<>"修改",S4<>""),"只有「修改」才需填代碼","")) | AA4: 13aeb2cf4e45fd614990924e
A5: 4 | B5: 2026-10-25 | C5: ADP | D5: Automatic Data Processing | E5: ADP implementation drops to 3.89pc in July-September | F5: 自動資料處理公司（ADP）在七至九月的實施率下降至3.89%，導致其信用違約掉期（CDS）利差擴大，顯示市場對其信用風險的擔憂升高。 | G5: The Financial Express | H5: -0.965 | I5: CDS_SPREAD_WIDENING | J5: CDS利差擴大／信用風險升高 | K5: 3 | L5: 已分類 | M5: 排除 | O5: 高 | P5: 文章談的是 ADP 實施率（與 Automatic Data Processing 無關）。 | R5: 排除 | T5: =IF(R5="維持",J5,IF(R5="排除","無關新聞事件",IFERROR(INDEX(事件規則!$B$2:$B$53,MATCH(S5,事件規則!$A$2:$A$53,0)),""))) -> 無關新聞事件 | U5: =IF(R5="維持",K5,IF(R5="排除",0,IFERROR(INDEX(事件規則!$C$2:$C$53,MATCH(S5,事件規則!$A$2:$A$53,0)),""))) -> 0 | X5: =IF(AND(R5="修改",S5=""),"請選新事件代碼",IF(AND(R5<>"修改",S5<>""),"只有「修改」才需填代碼","")) | AA5: 8a519af9cbc36c7c5948edab
A6: 5 | B6: 2026-08-09 | C6: MSFT | D6: Microsoft Corporation | E6: Microsoft releases Windows XP patch for WannaCrypt ransomware | F6: 微軟發布針對 WannaCrypt 勒索軟體的 Windows XP 補丁 | G6: Mashable | H6: -0.128 | I6: CYBER_ATTACK | J6: 資安攻擊 | K6: 3 | M6: 排除 | O6: 高 | P6: Windows XP WannaCrypt 修補程式為多年前舊聞，非新事件。 | R6: 排除 | T6: =IF(R6="維持",J6,IF(R6="排除","無關新聞事件",IFERROR(INDEX(事件規則!$B$2:$B$53,MATCH(S6,事件規則!$A$2:$A$53,0)),""))) -> 無關新聞事件 | U6: =IF(R6="維持",K6,IF(R6="排除",0,IFERROR(INDEX(事件規則!$C$2:$C$53,MATCH(S6,事件規則!$A$2:$A$53,0)),""))) -> 0 | X6: =IF(AND(R6="修改",S6=""),"請選新事件代碼",IF(AND(R6<>"修改",S6<>""),"只有「修改」才需填代碼","")) | AA6: 92d1743eeade3cb6fad4a889
A7: 6 | B7: 2026-08-10 | C7: MSFT | D7: Microsoft Corporation | E7: China-linked hackers turning popular cybersecurity tool into ransomware launchpad, Microsoft warns | F7: 微軟警告稱，與中國有關的駭客將流行的網路安全工具變成勒索軟體啟動板 | G7: The Record from Recorded Future News | H7: -0.078 | I7: CYBER_ATTACK | J7: 資安攻擊 | K7: 3 | M7: 排除 | O7: 中 | P7: Microsoft 是發出警告的一方，不是受害者。 | R7: 排除 | T7: =IF(R7="維持",J7,IF(R7="排除","無關新聞事件",IFERROR(INDEX(事件規則!$B$2:$B$53,MATCH(S7,事件規則!$A$2:$A$53,0)),""))) -> 無關新聞事件 | U7: =IF(R7="維持",K7,IF(R7="排除",0,IFERROR(INDEX(事件規則!$C$2:$C$53,MATCH(S7,事件規則!$A$2:$A$53,0)),""))) -> 0 | X7: =IF(AND(R7="修改",S7=""),"請選新事件代碼",IF(AND(R7<>"修改",S7<>""),"只有「修改」才需填代碼","")) | AA7: 988268a4ccf878c75da46a85
A8: 7 | B8: 2026-08-10 | C8: PSA | D8: Public Storage Common Stock | E8: PSA: Steam Machine and Steam Controller Customers in Europe Hit by Cyber Attack | F8: PSA：歐洲蒸汽機和蒸汽控制器客戶遭受網路攻擊 | G8: Digital Foundry | H8: -0.93 | I8: CYBER_ATTACK | J8: 資安攻擊 | K8: 3 | M8: 排除 | O8: 高 | P8: PSA 為「公共服務公告」，Steam 受攻擊與 Public Storage 無關。 | R8: 排除 | T8: =IF(R8="維持",J8,IF(R8="排除","無關新聞事件",IFERROR(INDEX(事件規則!$B$2:$B$53,MATCH(S8,事件規則!$A$2:$A$53,0)),""))) -> 無關新聞事件 | U8: =IF(R8="維持",K8,IF(R8="排除",0,IFERROR(INDEX(事件規則!$C$2:$C$53,MATCH(S8,事件規則!$A$2:$A$53,0)),""))) -> 0 | X8: =IF(AND(R8="修改",S8=""),"請選新事件代碼",IF(AND(R8<>"修改",S8<>""),"只有「修改」才需填代碼","")) | AA8: 408f0cdda38cf445ebf777d7
A9: 8 | B9: 2026-08-11 | C9: PSA | D9: Public Storage Common Stock | E9: PSA: Steam users have been hit by a cyber attack, ‘expect fake messages’ | F9: PSA：Steam 用戶遭受網路攻擊，“預計會出現虛假消息” | G9: Destructoid | H9: -0.922 | I9: CYBER_ATTACK | J9: 資安攻擊 | K9: 3 | M9: 排除 | O9: 高 | P9: PSA 為「公共服務公告」，Steam 受攻擊與 Public Storage 無關。 | R9: 排除 | T9: =IF(R9="維持",J9,IF(R9="排除","無關新聞事件",IFERROR(INDEX(事件規則!$B$2:$B$53,MATCH(S9,事件規則!$A$2:$A$53,0)),""))) -> 無關新聞事件 | U9: =IF(R9="維持",K9,IF(R9="排除",0,IFERROR(INDEX(事件規則!$C$2:$C$53,MATCH(S9,事件規則!$A$2:$A$53,0)),""))) -> 0 | X9: =IF(AND(R9="修改",S9=""),"請選新事件代碼",IF(AND(R9<>"修改",S9<>""),"只有「修改」才需填代碼","")) | AA9: 5aadece27ff463eaa8dce614
A10: 9 | B10: 2026-08-12 | C10: CRWD | D10: CrowdStrike | E10: AI驚傳脫序駭客事件！資安成下一波投資熱潮 專家點名 Palo Alto、CrowdStrike率先受惠 | F10: AI驚傳脫序駭客事件！資安成下一波投資熱潮 專家點名 Palo Alto、CrowdStrike率先受惠 | G10: 鉅亨網 | I10: CYBER_ATTACK | J10: 資安攻擊 | K10: 3 | M10: 排除 | O10: 高 | P10: 資安股投資評論／財報，不是這些公司遭攻擊。 | R10: 排除 | T10: =IF(R10="維持",J10,IF(R10="排除","無關新聞事件",IFERROR(INDEX(事件規則!$B$2:$B$53,MATCH(S10,事件規則!$A$2:$A$53,0)),""))) -> 無關新聞事件 | U10: =IF(R10="維持",K10,IF(R10="排除",0,IFERROR(INDEX(事件規則!$C$2:$C$53,MATCH(S10,事件規則!$A$2:$A$53,0)),""))) -> 0 | X10: =IF(AND(R10="修改",S10=""),"請選新事件代碼",IF(AND(R10<>"修改",S10<>""),"只有「修改」才需填代碼","")) | AA10: 02141c3c46d649e9c1225f18
A11: 10 | B11: 2026-09-02 | C11: PANW | D11: Palo Alto Networks, Inc. | E11: AI資安需求升温，Palo Alto Networks Q4業績及指引均勝預期 | G11: TradingView | I11: CYBER_ATTACK | J11: 資安攻擊 | K11: 3 | M11: 排除 | O11: 高 | P11: 資安股投資評論／財報，不是這些公司遭攻擊。 | R11: 排除 | T11: =IF(R11="維持",J11,IF(R11="排除","無關新聞事件",IFERROR(INDEX(事件規則!$B$2:$B$53,MATCH(S11,事件規則!$A$2:$A$53,0)),""))) -> 無關新聞事件 | U11: =IF(R11="維持",K11,IF(R11="排除",0,IFERROR(INDEX(事件規則!$C$2:$C$53,MATCH(S11,事件規則!$A$2:$A$53,0)),""))) -> 0 | X11: =IF(AND(R11="修改",S11=""),"請選新事件代碼",IF(AND(R11<>"修改",S11<>""),"只有「修改」才需填代碼","")) | AA11: 604f5199f8da58eb0972fb4b
A12: 11 | B12: 2026-09-09 | C12: T | D12: AT&T Inc. | E12: Iranian group claims responsibility for AT&T cyber attack | G12: FOX 4 News Dallas-Fort Worth | H12: -0.49 | I12: CYBER_ATTACK | J12: 資安攻擊 | K12: 3 | M12: 維持 | O12: 中 | P12: 伊朗組織宣稱對 AT&T 發動網路攻擊；屬對方宣稱，尚待證實。 | R12: 維持 | T12: =IF(R12="維持",J12,IF(R12="排除","無關新聞事件",IFERROR(INDEX(事件規則!$B$2:$B$53,MATCH(S12,事件規則!$A$2:$A$53,0)),""))) -> 資安攻擊 | U12: =IF(R12="維持",K12,IF(R12="排除",0,IFERROR(INDEX(事件規則!$C$2:$C$53,MATCH(S12,事件規則!$A$2:$A$53,0)),""))) -> 3 | X12: =IF(AND(R12="修改",S12=""),"請選新事件代碼",IF(AND(R12<>"修改",S12<>""),"只有「修改」才需填代碼","")) | AA12: 56a8e6d9f7d9285ccbceac4d
A13: 12 | B13: 2026-09-10 | C13: CSCO | D13: Cisco | E13: Cisco FMC bugs exploited by nation-state and ransomware actors (CVE-2026-20079, CVE-2026-20316) | G13: Help Net Security | H13: -0.572 | I13: CYBER_ATTACK | J13: 資安攻擊 | K13: 3 | M13: 維持 | O13: 中 | P13: Cisco FMC 軟體漏洞被國家級與勒索軟體組織利用，屬產品瑕疵，Cisco 本身未被入侵。 | R13: 維持 | T13: =IF(R13="維持",J13,IF(R13="排除","無關新聞事件",IFERROR(INDEX(事件規則!$B$2:$B$53,MATCH(S13,事件規則!$A$2:$A$53,0)),""))) -> 資安攻擊 | U13: =IF(R13="維持",K13,IF(R13="排除",0,IFERROR(INDEX(事件規則!$C$2:$C$53,MATCH(S13,事件規則!$A$2:$A$53,0)),""))) -> 3 | X13: =IF(AND(R13="修改",S13=""),"請選新事件代碼",IF(AND(R13<>"修改",S13<>""),"只有「修改」才需填代碼","")) | AA13: 6d8450cf1d2478dab7cfdd9a
A14: 13 | B14: 2026-09-11 | C14: CSCO | D14: Cisco | E14: Cisco FMC Flaws Exploited to Steal Credentials and Deploy Qilin Ransomware | G14: The Hacker News | H14: -0.751 | I14: CYBER_ATTACK | J14: 資安攻擊 | K14: 3 | M14: 維持 | O14: 中 | P14: Cisco FMC 軟體漏洞被國家級與勒索軟體組織利用，屬產品瑕疵，Cisco 本身未被入侵。 | R14: 維持 | T14: =IF(R14="維持",J14,IF(R14="排除","無關新聞事件",IFERROR(INDEX(事件規則!$B$2:$B$53,MATCH(S14,事件規則!$A$2:$A$53,0)),""))) -> 資安攻擊 | U14: =IF(R14="維持",K14,IF(R14="排除",0,IFERROR(INDEX(事件規則!$C$2:$C$53,MATCH(S14,事件規則!$A$2:$A$53,0)),""))) -> 3 | X14: =IF(AND(R14="修改",S14=""),"請選新事件代碼",IF(AND(R14<>"修改",S14<>""),"只有「修改」才需填代碼","")) | AA14: acb74955c92e417543c27e22
A15: 14 | B15: 2026-10-07 | C15: BA | D15: Boeing | E15: Ransomware gang targets FlyDubai - and says it has Boeing's code | G15: Insurance Business | H15: -0.304 | I15: CYBER_ATTACK | J15: 資安攻擊 | K15: 3 | M15: 維持 | O15: 中 | P15: 勒索軟體組織宣稱透過 FlyDubai 取得波音程式碼；屬對方宣稱。 | R15: 維持 | T15: =IF(R15="維持",J15,IF(R15="排除","無關新聞事件",IFERROR(INDEX(事件規則!$B$2:$B$53,MATCH(S15,事件規則!$A$2:$A$53,0)),""))) -> 資安攻擊 | U15: =IF(R15="維持",K15,IF(R15="排除",0,IFERROR(INDEX(事件規則!$C$2:$C$53,MATCH(S15,事件規則!$A$2:$A$53,0)),""))) -> 3 | X15: =IF(AND(R15="修改",S15=""),"請選新事件代碼",IF(AND(R15<>"修改",S15<>""),"只有「修改」才需填代碼","")) | AA15: c4048d11214374f0ea66a073
A16: 15 | B16: 2026-10-09 | C16: BA | D16: Boeing | E16: Flydubai and Boeing: Targets of Everest Ransomware Campaign | G16: Cyber Magazine | H16: -0.016 | I16: CYBER_ATTACK | J16: 資安攻擊 | K16: 3 | M16: 維持 | O16: 中 | P16: 勒索軟體組織宣稱透過 FlyDubai 取得波音程式碼；屬對方宣稱。 | R16: 維持 | T16: =IF(R16="維持",J16,IF(R16="排除","無關新聞事件",IFERROR(INDEX(事件規則!$B$2:$B$53,MATCH(S16,事件規則!$A$2:$A$53,0)),""))) -> 資安攻擊 | U16: =IF(R16="維持",K16,IF(R16="排除",0,IFERROR(INDEX(事件規則!$C$2:$C$53,MATCH(S16,事件規則!$A$2:$A$53,0)),""))) -> 3 | X16: =IF(AND(R16="修改",S16=""),"請選新事件代碼",IF(AND(R16<>"修改",S16<>""),"只有「修改」才需填代碼","")) | AA16: 07b4a0c0b95defc58dd555c3
A17: 16 | B17: 2026-08-13 | C17: UBER | D17: Uber Technologies, Inc. Common Stock | E17: Uber Freight reportedly investigating after hacking group claims data breach | F17: 據報道，Uber Freight 在駭客組織聲稱資料外洩後正在進行調查 | G17: TechCrunch | H17: -0.925 | I17: DATA_BREACH | J17: 資料外洩 | K17: 3 | M17: 維持 | O17: 中 | P17: 駭客組織宣稱入侵 Uber Freight，公司調查中。 | R17: 維持 | T17: =IF(R17="維持",J17,IF(R17="排除","無關新聞事件",IFERROR(INDEX(事件規則!$B$2:$B$53,MATCH(S17,事件規則!$A$2:$A$53,0)),""))) -> 資料外洩 | U17: =IF(R17="維持",K17,IF(R17="排除",0,IFERROR(INDEX(事件規則!$C$2:$C$53,MATCH(S17,事件規則!$A$2:$A$53,0)),""))) -> 3 | X17: =IF(AND(R17="修改",S17=""),"請選新事件代碼",IF(AND(R17<>"修改",S17<>""),"只有「修改」才需填代碼","")) | AA17: dd7f2946f86b0678ab55f27b
A18: 17 | B18: 2026-08-14 | C18: CRM | D18: Salesforce, Inc. Common Stock | E18: Over 1,000 Charities Hit by Beacon CRM Data Breach | F18: 超過 1,000 個慈善機構受到 Beacon CRM 資料外洩的影響 | G18: SecurityWeek | H18: -0.938 | I18: DATA_BREACH | J18: 資料外洩 | K18: 3 | M18: 排除 | O18: 高 | P18: Beacon CRM 是另一家供應商，非 Salesforce。 | R18: 排除 | T18: =IF(R18="維持",J18,IF(R18="排除","無關新聞事件",IFERROR(INDEX(事件規則!$B$2:$B$53,MATCH(S18,事件規則!$A$2:$A$53,0)),""))) -> 無關新聞事件 | U18: =IF(R18="維持",K18,IF(R18="排除",0,IFERROR(INDEX(事件規則!$C$2:$C$53,MATCH(S18,事件規則!$A$2:$A$53,0)),""))) -> 0 | X18: =IF(AND(R18="修改",S18=""),"請選新事件代碼",IF(AND(R18<>"修改",S18<>""),"只有「修改」才需填代碼","")) | AA18: 63e55ad1310d4ec1dd5066ec
A19: 18 | B19: 2026-08-15 | C19: LEN | D19: Lennar Corporation Class A Common Stock | E19: Lennar Corporation Data Breach Alert: Edelson Lechtzin LLP Launches Investigation Into Exposure of Personal Information | F19: Lennar Corporation 資料外洩警報：Edelson Lechtzin LLP 啟動針對個人資訊外洩的調查 | G19: The Daily Tribune News | H19: -0.591 | I19: DATA_BREACH | J19: 資料外洩 | K19: 3 | M19: 排除 | O19: 中 | P19: 律師事務所對 Lennar 資料外洩的徵求公告，事件已有其他報導。 | R19: 排除 | T19: =IF(R19="維持",J19,IF(R19="排除","無關新聞事件",IFERROR(INDEX(事件規則!$B$2:$B$53,MATCH(S19,事件規則!$A$2:$A$53,0)),""))) -> 無關新聞事件 | U19: =IF(R19="維持",K19,IF(R19="排除",0,IFERROR(INDEX(事件規則!$C$2:$C$53,MATCH(S19,事件規則!$A$2:$A$53,0)),""))) -> 0 | X19: =IF(AND(R19="修改",S19=""),"請選新事件代碼",IF(AND(R19<>"修改",S19<>""),"只有「修改」才需填代碼","")) | AA19: 4fcff80cbae75add25c9574a
A20: 19 | B20: 2026-08-15 | C20: LEN | D20: Lennar Corporation Class A Common Stock | E20: Lennar Corporation Data Breach Alert: Edelson Lechtzin LLP | F20: Lennar 公司資料外洩警報：Edelson Lechtzin LLP | G20: GlobeNewswire | H20: -0.07 | I20: DATA_BREACH | J20: 資料外洩 | K20: 3 | M20: 排除 | O20: 中 | P20: 律師事務所對 Lennar 資料外洩的徵求公告，事件已有其他報導。 | R20: 排除 | T20: =IF(R20="維持",J20,IF(R20="排除","無關新聞事件",IFERROR(INDEX(事件規則!$B$2:$B$53,MATCH(S20,事件規則!$A$2:$A$53,0)),""))) -> 無關新聞事件 | U20: =IF(R20="維持",K20,IF(R20="排除",0,IFERROR(INDEX(事件規則!$C$2:$C$53,MATCH(S20,事件規則!$A$2:$A$53,0)),""))) -> 0 | X20: =IF(AND(R20="修改",S20=""),"請選新事件代碼",IF(AND(R20<>"修改",S20<>""),"只有「修改」才需填代碼","")) | AA20: 1afc9ccb94eb0aab4b6f9d71
A21: 20 | B21: 2026-08-15 | C21: LEN | D21: Lennar Corporation Class A Common Stock | E21: Lennar Mortgage Data Breach Lawsuit Investigation | F21: Lennar 抵押貸款資料外洩訴訟調查 | G21: Claim Depot | H21: -0.859 | I21: DATA_BREACH | J21: 資料外洩 | K21: 3 | M21: 排除 | O21: 中 | P21: 律師事務所對 Lennar 資料外洩的徵求公告，事件已有其他報導。 | R21: 排除 | T21: =IF(R21="維持",J21,IF(R21="排除","無關新聞事件",IFERROR(INDEX(事件規則!$B$2:$B$53,MATCH(S21,事件規則!$A$2:$A$53,0)),""))) -> 無關新聞事件 | U21: =IF(R21="維持",K21,IF(R21="排除",0,IFERROR(INDEX(事件規則!$C$2:$C$53,MATCH(S21,事件規則!$A$2:$A$53,0)),""))) -> 0 | X21: =IF(AND(R21="修改",S21=""),"請選新事件代碼",IF(AND(R21<>"修改",S21<>""),"只有「修改」才需填代碼","")) | AA21: 3369449d738b1f178a63c13a
A22: 21 | B22: 2026-08-15 | C22: LEN | D22: Lennar Corporation Class A Common Stock | E22: Lennar Mortgage Data Breach Affects 60,526 Texans | F22: Lennar 抵押貸款資料外洩影響 60,526 名德州人 | G22: Claim Depot | H22: -0.333 | I22: DATA_BREACH | J22: 資料外洩 | K22: 3 | M22: 維持 | O22: 高 | P22: Lennar Mortgage 資料外洩，影響 60,526 名德州居民（含相關訴訟）。 | R22: 維持 | T22: =IF(R22="維持",J22,IF(R22="排除","無關新聞事件",IFERROR(INDEX(事件規則!$B$2:$B$53,MATCH(S22,事件規則!$A$2:$A$53,0)),""))) -> 資料外洩 | U22: =IF(R22="維持",K22,IF(R22="排除",0,IFERROR(INDEX(事件規則!$C$2:$C$53,MATCH(S22,事件規則!$A$2:$A$53,0)),""))) -> 3 | X22: =IF(AND(R22="修改",S22=""),"請選新事件代碼",IF(AND(R22<>"修改",S22<>""),"只有「修改」才需填代碼","")) | AA22: 594eaa985b351c2648b735eb
A23: 22 | B23: 2026-08-16 | C23: DOW | D23: Dow Inc. Common Stock | E23: Bloomberg Money Minute: Dow Hits Record High As SpaceX Plunges Canada Revenue Agency Data Breaches (Kz5b0Hg4QP) | F23: 彭博財經紀要：隨著 SpaceX 暴跌，道瓊指數創下歷史新高 加拿大稅務局資料外洩 (Kz5b0Hg4QP) | G23: Mshale | H23: 0.197 | I23: DATA_BREACH | J23: 資料外洩 | K23: 3 | M23: 排除 | O23: 高 | P23: Bloomberg 市場快報標題，資料外洩指加拿大稅務局，與 Dow 無關。 | R23: 排除 | T23: =IF(R23="維持",J23,IF(R23="排除","無關新聞事件",IFERROR(INDEX(事件規則!$B$2:$B$53,MATCH(S23,事件規則!$A$2:$A$53,0)),""))) -> 無關新聞事件 | U23: =IF(R23="維持",K23,IF(R23="排除",0,IFERROR(INDEX(事件規則!$C$2:$C$53,MATCH(S23,事件規則!$A$2:$A$53,0)),""))) -> 0 | X23: =IF(AND(R23="修改",S23=""),"請選新事件代碼",IF(AND(R23<>"修改",S23<>""),"只有「修改」才需填代碼","")) | AA23: 7031ef56aea01413bbc14779
A24: 23 | B24: 2026-08-17 | C24: IBM | D24: International Business Machines Corporat | E24: IBM: ASEAN data breach costs hit record US$4.12 million as AI attacks rise | F24: IBM：隨著人工智慧攻擊的增加，東協資料外洩成本達到創紀錄的 412 萬美元 | G24: crnasia.com | H24: 0.306 | I24: DATA_BREACH | J24: 資料外洩 | K24: 3 | M24: 排除 | O24: 高 | P24: IBM 發布的資料外洩成本報告，不是 IBM 自身事件。 | R24: 排除 | T24: =IF(R24="維持",J24,IF(R24="排除","無關新聞事件",IFERROR(INDEX(事件規則!$B$2:$B$53,MATCH(S24,事件規則!$A$2:$A$53,0)),""))) -> 無關新聞事件 | U24: =IF(R24="維持",K24,IF(R24="排除",0,IFERROR(INDEX(事件規則!$C$2:$C$53,MATCH(S24,事件規則!$A$2:$A$53,0)),""))) -> 0 | X24: =IF(AND(R24="修改",S24=""),"請選新事件代碼",IF(AND(R24<>"修改",S24<>""),"只有「修改」才需填代碼","")) | AA24: 9cecc970db7ffabca16030b6
A25: 24 | B25: 2026-08-19 | C25: LEN | D25: Lennar Corporation Class A Common Stock | E25: News - Lennar Mortgage data breach exposes personal information of more than 60,000 Texans | G25: teiss | H25: -0.926 | I25: DATA_BREACH | J25: 資料外洩 | K25: 3 | M25: 維持 | O25: 高 | P25: Lennar Mortgage 資料外洩，影響 60,526 名德州居民（含相關訴訟）。 | R25: 維持 | T25: =IF(R25="維持",J25,IF(R25="排除","無關新聞事件",IFERROR(INDEX(事件規則!$B$2:$B$53,MATCH(S25,事件規則!$A$2:$A$53,0)),""))) -> 資料外洩 | U25: =IF(R25="維持",K25,IF(R25="排除",0,IFERROR(INDEX(事件規則!$C$2:$C$53,MATCH(S25,事件規則!$A$2:$A$53,0)),""))) -> 3 | X25: =IF(AND(R25="修改",S25=""),"請選新事件代碼",IF(AND(R25<>"修改",S25<>""),"只有「修改」才需填代碼","")) | AA25: 98248d8bb5062e16bbdce959
A26: 25 | B26: 2026-08-20 | C26: CTSH | D26: Cognizant | E26: Cognizant Data Breach Lawsuit Investigation | G26: Claim Depot | H26: -0.767 | I26: DATA_BREACH | J26: 資料外洩 | K26: 3 | M26: 維持 | O26: 低 | P26: 「Cognizant 資料外洩訴訟調查」，內容僅為標題，請看原文確認是否有實際外洩。 | Q26: 是 | R26: 維持 | T26: =IF(R26="維持",J26,IF(R26="排除","無關新聞事件",IFERROR(INDEX(事件規則!$B$2:$B$53,MATCH(S26,事件規則!$A$2:$A$53,0)),""))) -> 資料外洩 | U26: =IF(R26="維持",K26,IF(R26="排除",0,IFERROR(INDEX(事件規則!$C$2:$C$53,MATCH(S26,事件規則!$A$2:$A$53,0)),""))) -> 3 | X26: =IF(AND(R26="修改",S26=""),"請選新事件代碼",IF(AND(R26<>"修改",S26<>""),"只有「修改」才需填代碼","")) | AA26: 3d33575d263b136c4a43c7fa
A27: 26 | B27: 2026-08-20 | C27: IBM | D27: International Business Machines Corporat | E27: IBM’s 2026 Data Breach Report: Houston, We Have A Problem | G27: Above the Law | H27: -0.946 | I27: DATA_BREACH | J27: 資料外洩 | K27: 3 | M27: 排除 | O27: 高 | P27: IBM 發布的資料外洩成本報告，不是 IBM 自身事件。 | R27: 排除 | T27: =IF(R27="維持",J27,IF(R27="排除","無關新聞事件",IFERROR(INDEX(事件規則!$B$2:$B$53,MATCH(S27,事件規則!$A$2:$A$53,0)),""))) -> 無關新聞事件 | U27: =IF(R27="維持",K27,IF(R27="排除",0,IFERROR(INDEX(事件規則!$C$2:$C$53,MATCH(S27,事件規則!$A$2:$A$53,0)),""))) -> 0 | X27: =IF(AND(R27="修改",S27=""),"請選新事件代碼",IF(AND(R27<>"修改",S27<>""),"只有「修改」才需填代碼","")) | AA27: b5fb7ce9cc34eee18630b78a
A28: 27 | B28: 2026-08-21 | C28: APO | D28: Apollo Global Management | E28: Apollo Global Management Data Breach Impacts SSNs; Lawsuit Possible | G28: classaction.org | H28: -0.933 | I28: DATA_BREACH | J28: 資料外洩 | K28: 3 | M28: 維持 | O28: 中 | P28: Apollo 資料外洩涉及社會安全號碼，可能提起訴訟。 | R28: 維持 | T28: =IF(R28="維持",J28,IF(R28="排除","無關新聞事件",IFERROR(INDEX(事件規則!$B$2:$B$53,MATCH(S28,事件規則!$A$2:$A$53,0)),""))) -> 資料外洩 | U28: =IF(R28="維持",K28,IF(R28="排除",0,IFERROR(INDEX(事件規則!$C$2:$C$53,MATCH(S28,事件規則!$A$2:$A$53,0)),""))) -> 3 | X28: =IF(AND(R28="修改",S28=""),"請選新事件代碼",IF(AND(R28<>"修改",S28<>""),"只有「修改」才需填代碼","")) | AA28: 95def5878b484fab12e3ab5e
A29: 28 | B29: 2026-09-03 | C29: DVA | D29: DaVita Inc. Common Stock | E29: DaVita agrees to pay $15M to settle claims from data breach | G29: Healthcare Dive | H29: 0.515 | I29: DATA_BREACH | J29: 資料外洩 | K29: 3 | M29: 維持 | O29: 高 | P29: DaVita 以 1,500 萬美元和解資料外洩索賠。 | R29: 維持 | T29: =IF(R29="維持",J29,IF(R29="排除","無關新聞事件",IFERROR(INDEX(事件規則!$B$2:$B$53,MATCH(S29,事件規則!$A$2:$A$53,0)),""))) -> 資料外洩 | U29: =IF(R29="維持",K29,IF(R29="排除",0,IFERROR(INDEX(事件規則!$C$2:$C$53,MATCH(S29,事件規則!$A$2:$A$53,0)),""))) -> 3 | X29: =IF(AND(R29="修改",S29=""),"請選新事件代碼",IF(AND(R29<>"修改",S29<>""),"只有「修改」才需填代碼","")) | AA29: a18c5f8cc1d23cf00e4d9c8a
A30: 29 | B30: 2026-09-08 | C30: LEN | D30: Lennar Corporation Class A Common Stock | E30: Lennar data breach lawsuit takes aim at company’s lax data security | G30: Top Class Actions | H30: -0.893 | I30: DATA_BREACH | J30: 資料外洩 | K30: 3 | M30: 維持 | O30: 高 | P30: Lennar Mortgage 資料外洩，影響 60,526 名德州居民（含相關訴訟）。 | R30: 維持 | T30: =IF(R30="維持",J30,IF(R30="排除","無關新聞事件",IFERROR(INDEX(事件規則!$B$2:$B$53,MATCH(S30,事件規則!$A$2:$A$53,0)),""))) -> 資料外洩 | U30: =IF(R30="維持",K30,IF(R30="排除",0,IFERROR(INDEX(事件規則!$C$2:$C$53,MATCH(S30,事件規則!$A$2:$A$53,0)),""))) -> 3 | X30: =IF(AND(R30="修改",S30=""),"請選新事件代碼",IF(AND(R30<>"修改",S30<>""),"只有「修改」才需填代碼","")) | AA30: 684239e1c4e7e3d7964a7f70
A31: 30 | B31: 2026-09-17 | C31: IBM | D31: International Business Machines Corporat | E31: IBM, J&J Get Incurable Data Breach Suit Tossed For Good | G31: Law360 | H31: -0.72 | I31: DATA_BREACH | J31: 資料外洩 | K31: 3 | M31: 排除 | O31: 中 | P31: IBM、J&J 的資料外洩訴訟被永久駁回，對公司為正面。 | R31: 排除 | T31: =IF(R31="維持",J31,IF(R31="排除","無關新聞事件",IFERROR(INDEX(事件規則!$B$2:$B$53,MATCH(S31,事件規則!$A$2:$A$53,0)),""))) -> 無關新聞事件 | U31: =IF(R31="維持",K31,IF(R31="排除",0,IFERROR(INDEX(事件規則!$C$2:$C$53,MATCH(S31,事件規則!$A$2:$A$53,0)),""))) -> 0 | X31: =IF(AND(R31="修改",S31=""),"請選新事件代碼",IF(AND(R31<>"修改",S31<>""),"只有「修改」才需填代碼","")) | AA31: 6ce8773304d44f52a85c5ca6
A32: 31 | B32: 2026-09-25 | C32: LH | D32: Labcorp | E32: Labcorp Settles Multistate Data Breach Investigation for $2.3 Million | G32: The HIPAA Journal | H32: -0.147 | I32: DATA_BREACH | J32: 資料外洩 | K32: 3 | M32: 維持 | O32: 高 | P32: Labcorp 以 230 萬美元和解多州資料外洩調查。 | R32: 維持 | T32: =IF(R32="維持",J32,IF(R32="排除","無關新聞事件",IFERROR(INDEX(事件規則!$B$2:$B$53,MATCH(S32,事件規則!$A$2:$A$53,0)),""))) -> 資料外洩 | U32: =IF(R32="維持",K32,IF(R32="排除",0,IFERROR(INDEX(事件規則!$C$2:$C$53,MATCH(S32,事件規則!$A$2:$A$53,0)),""))) -> 3 | X32: =IF(AND(R32="修改",S32=""),"請選新事件代碼",IF(AND(R32<>"修改",S32<>""),"只有「修改」才需填代碼","")) | AA32: 23ba8f3784dba1f0cb7e8c17
A33: 32 | B33: 2026-10-05 | C33: ACN | D33: Accenture plc Class A Ordinary Shares (I | E33: EXCLUSIVE: Accenture contractor removed from FBI following damaging data breach, sources say | G33: Reuters | H33: -0.936 | I33: DATA_BREACH | J33: 資料外洩 | K33: 3 | M33: 維持 | O33: 高 | P33: FBI 因資料外洩與未修補漏洞，終止與 Accenture 承包商合作。 | R33: 維持 | T33: =IF(R33="維持",J33,IF(R33="排除","無關新聞事件",IFERROR(INDEX(事件規則!$B$2:$B$53,MATCH(S33,事件規則!$A$2:$A$53,0)),""))) -> 資料外洩 | U33: =IF(R33="維持",K33,IF(R33="排除",0,IFERROR(INDEX(事件規則!$C$2:$C$53,MATCH(S33,事件規則!$A$2:$A$53,0)),""))) -> 3 | X33: =IF(AND(R33="修改",S33=""),"請選新事件代碼",IF(AND(R33<>"修改",S33<>""),"只有「修改」才需填代碼","")) | AA33: 0c94db61ca0b7844387a6c13
A34: 33 | B34: 2026-10-06 | C34: ACN | D34: Accenture plc Class A Ordinary Shares (I | E34: FBI Cuts Ties With Accenture After Missed Security Patch Linked To Data Breach | G34: LinkedIn | H34: -0.932 | I34: DATA_BREACH | J34: 資料外洩 | K34: 3 | M34: 維持 | O34: 高 | P34: FBI 因資料外洩與未修補漏洞，終止與 Accenture 承包商合作。 | R34: 維持 | T34: =IF(R34="維持",J34,IF(R34="排除","無關新聞事件",IFERROR(INDEX(事件規則!$B$2:$B$53,MATCH(S34,事件規則!$A$2:$A$53,0)),""))) -> 資料外洩 | U34: =IF(R34="維持",K34,IF(R34="排除",0,IFERROR(INDEX(事件規則!$C$2:$C$53,MATCH(S34,事件規則!$A$2:$A$53,0)),""))) -> 3 | X34: =IF(AND(R34="修改",S34=""),"請選新事件代碼",IF(AND(R34<>"修改",S34<>""),"只有「修改」才需填代碼","")) | AA34: e670fbcc9435d64e497e916b
A35: 34 | B35: 2026-10-06 | C35: ACN | D35: Accenture plc Class A Ordinary Shares (I | E35: FBI removed an Accenture contractor after a data breach exposed thousands of employees' records | G35: Quartz | H35: -0.942 | I35: DATA_BREACH | J35: 資料外洩 | K35: 3 | M35: 維持 | O35: 高 | P35: FBI 因資料外洩與未修補漏洞，終止與 Accenture 承包商合作。 | R35: 維持 | T35: =IF(R35="維持",J35,IF(R35="排除","無關新聞事件",IFERROR(INDEX(事件規則!$B$2:$B$53,MATCH(S35,事件規則!$A$2:$A$53,0)),""))) -> 資料外洩 | U35: =IF(R35="維持",K35,IF(R35="排除",0,IFERROR(INDEX(事件規則!$C$2:$C$53,MATCH(S35,事件規則!$A$2:$A$53,0)),""))) -> 3 | X35: =IF(AND(R35="修改",S35=""),"請選新事件代碼",IF(AND(R35<>"修改",S35<>""),"只有「修改」才需填代碼","")) | AA35: 3c3c6443bddbd1fa0ca616a7
A36: 35 | B36: 2026-10-08 | C36: GS | D36: Goldman Sachs | E36: Goldman Sachs Ensnared in EY Data Breach Earlier This Year | G36: Claims Journal | H36: -0.847 | I36: DATA_BREACH | J36: 資料外洩 | K36: 3 | M36: 維持 | O36: 中 | P36: Goldman Sachs 受 EY 資料外洩牽連（第三方事件）。 | R36: 維持 | T36: =IF(R36="維持",J36,IF(R36="排除","無關新聞事件",IFERROR(INDEX(事件規則!$B$2:$B$53,MATCH(S36,事件規則!$A$2:$A$53,0)),""))) -> 資料外洩 | U36: =IF(R36="維持",K36,IF(R36="排除",0,IFERROR(INDEX(事件規則!$C$2:$C$53,MATCH(S36,事件規則!$A$2:$A$53,0)),""))) -> 3 | X36: =IF(AND(R36="修改",S36=""),"請選新事件代碼",IF(AND(R36<>"修改",S36<>""),"只有「修改」才需填代碼","")) | AA36: 0c48ccb7c65f57c24ba2ac79
A37: 36 | B37: 2026-10-15 | C37: CNP | D37: CenterPoint Energy | E37: 1M Impacted by CenterPoint Energy Data Breach | F37: 100 萬人受到 CenterPoint 能源資料外洩的影響 | G37: Security Magazine | H37: -0.954 | I37: DATA_BREACH | J37: 資料外洩 | K37: 3 | M37: 維持 | O37: 高 | P37: CenterPoint Energy 資料外洩影響逾 100 萬名客戶。 | R37: 維持 | T37: =IF(R37="維持",J37,IF(R37="排除","無關新聞事件",IFERROR(INDEX(事件規則!$B$2:$B$53,MATCH(S37,事件規則!$A$2:$A$53,0)),""))) -> 資料外洩 | U37: =IF(R37="維持",K37,IF(R37="排除",0,IFERROR(INDEX(事件規則!$C$2:$C$53,MATCH(S37,事件規則!$A$2:$A$53,0)),""))) -> 3 | X37: =IF(AND(R37="修改",S37=""),"請選新事件代碼",IF(AND(R37<>"修改",S37<>""),"只有「修改」才需填代碼","")) | AA37: 526c02dc8a51f4dfb3eed28b
A38: 37 | B38: 2026-10-15 | C38: CNP | D38: CenterPoint Energy | E38: More than 1 million customers affected in CenterPoint Energy data breach, Texas DA’s office says | F38: 德州地方檢察官辦公室表示，超過 100 萬名客戶因 CenterPoint Energy 資料外洩而受到影響 | G38: CW39 Houston | H38: -0.919 | I38: DATA_BREACH | J38: 資料外洩 | K38: 3 | M38: 維持 | O38: 高 | P38: CenterPoint Energy 資料外洩影響逾 100 萬名客戶。 | R38: 維持 | T38: =IF(R38="維持",J38,IF(R38="排除","無關新聞事件",IFERROR(INDEX(事件規則!$B$2:$B$53,MATCH(S38,事件規則!$A$2:$A$53,0)),""))) -> 資料外洩 | U38: =IF(R38="維持",K38,IF(R38="排除",0,IFERROR(INDEX(事件規則!$C$2:$C$53,MATCH(S38,事件規則!$A$2:$A$53,0)),""))) -> 3 | X38: =IF(AND(R38="修改",S38=""),"請選新事件代碼",IF(AND(R38<>"修改",S38<>""),"只有「修改」才需填代碼","")) | AA38: a160021d837a200295fca910
A39: 38 | B39: 2026-10-15 | C39: CNP | D39: CenterPoint Energy | E39: CenterPoint Energy Data Breach Impacts 1 Million Texans | F39: CenterPoint 能源資料外洩影響 100 萬德州人 | G39: SecurityWeek | H39: -0.445 | I39: DATA_BREACH | J39: 資料外洩 | K39: 3 | M39: 維持 | O39: 高 | P39: CenterPoint Energy 資料外洩影響逾 100 萬名客戶。 | R39: 維持 | T39: =IF(R39="維持",J39,IF(R39="排除","無關新聞事件",IFERROR(INDEX(事件規則!$B$2:$B$53,MATCH(S39,事件規則!$A$2:$A$53,0)),""))) -> 資料外洩 | U39: =IF(R39="維持",K39,IF(R39="排除",0,IFERROR(INDEX(事件規則!$C$2:$C$53,MATCH(S39,事件規則!$A$2:$A$53,0)),""))) -> 3 | X39: =IF(AND(R39="修改",S39=""),"請選新事件代碼",IF(AND(R39<>"修改",S39<>""),"只有「修改」才需填代碼","")) | AA39: fa26c8a2a64ef24eee780b89
A40: 39 | B40: 2026-10-15 | C40: CNP | D40: CenterPoint Energy | E40: More than 1 million customers impacted by CenterPoint Energy data breach, AG report filing shows | F40: AG 報告顯示，超過 100 萬名客戶受到 CenterPoint Energy 資料外洩的影響 | G40: ABC13 Houston | H40: -0.925 | I40: DATA_BREACH | J40: 資料外洩 | K40: 3 | M40: 維持 | O40: 高 | P40: CenterPoint Energy 資料外洩影響逾 100 萬名客戶。 | R40: 維持 | T40: =IF(R40="維持",J40,IF(R40="排除","無關新聞事件",IFERROR(INDEX(事件規則!$B$2:$B$53,MATCH(S40,事件規則!$A$2:$A$53,0)),""))) -> 資料外洩 | U40: =IF(R40="維持",K40,IF(R40="排除",0,IFERROR(INDEX(事件規則!$C$2:$C$53,MATCH(S40,事件規則!$A$2:$A$53,0)),""))) -> 3 | X40: =IF(AND(R40="修改",S40=""),"請選新事件代碼",IF(AND(R40<>"修改",S40<>""),"只有「修改」才需填代碼","")) | AA40: 28f260be7eac8f93590dbec7
...

Sheet 事件規則
A1: Event_Code | B1: 事件中文 | C1: Level
A2: ACCOUNTING_FRAUD | B2: 會計舞弊 | C2: 5
A3: BANKRUPTCY | B3: 破產 | C3: 5
A4: DEFAULT | B4: 違約 | C4: 5
A5: DELISTING | B5: 下市 | C5: 5
A6: GOING_CONCERN | B6: 繼續經營疑慮 | C6: 5
A7: LIQUIDITY_CRISIS | B7: 流動性危機 | C7: 5
A8: TRADING_SUSPENSION | B8: 停牌 | C8: 5
A9: ANTITRUST_INVESTIGATION | B9: 反壟斷調查 | C9: 4
A10: AUDITOR_RESIGNATION | B10: 會計師辭任 | C10: 4
A11: CREDIT_DOWNGRADE | B11: 信用調降 | C11: 4
A12: ENVIRONMENTAL_INCIDENT | B12: 重大環境事故 | C12: 4
A13: EXECUTIVE_MISCONDUCT | B13: 高管不當行為 | C13: 4
... A53: UNKNOWN | B53: 待人工覆核 | C53: 0
A55: 來源：negative-news 的 Parameter_Event.xlsx（Event 工作表），2026-10-26 讀取。
